<?xml version="1.0"?>
<!-- Simple differential-drive robot for testing the Nav2 Editor SDF import.
     Uses only primitive geometry, so no external meshes are required. -->
<sdf version="1.7">
  <model name="diffbot">
    <pose>0 0 0.1 0 0 0</pose>

    <link name="base_link">
      <pose>0 0 0.1 0 0 0</pose>
      <visual name="body_visual">
        <geometry>
          <box>
            <size>0.5 0.35 0.18</size>
          </box>
        </geometry>
        <material>
          <diffuse>0.2 0.5 0.9 1</diffuse>
        </material>
      </visual>
      <collision name="body_collision">
        <geometry>
          <box>
            <size>0.5 0.35 0.18</size>
          </box>
        </geometry>
      </collision>
    </link>

    <link name="left_wheel">
      <pose>0 0.21 0.06 1.5707 0 0</pose>
      <visual name="left_wheel_visual">
        <geometry>
          <cylinder>
            <radius>0.06</radius>
            <length>0.04</length>
          </cylinder>
        </geometry>
        <material>
          <diffuse>0.1 0.1 0.1 1</diffuse>
        </material>
      </visual>
    </link>

    <link name="right_wheel">
      <pose>0 -0.21 0.06 1.5707 0 0</pose>
      <visual name="right_wheel_visual">
        <geometry>
          <cylinder>
            <radius>0.06</radius>
            <length>0.04</length>
          </cylinder>
        </geometry>
        <material>
          <diffuse>0.1 0.1 0.1 1</diffuse>
        </material>
      </visual>
    </link>

    <link name="caster">
      <pose>0.2 0 0.03 0 0 0</pose>
      <visual name="caster_visual">
        <geometry>
          <sphere>
            <radius>0.03</radius>
          </sphere>
        </geometry>
        <material>
          <diffuse>0.6 0.6 0.6 1</diffuse>
        </material>
      </visual>
    </link>

    <joint name="left_wheel_joint" type="revolute">
      <parent>base_link</parent>
      <child>left_wheel</child>
      <axis>
        <xyz>0 1 0</xyz>
      </axis>
    </joint>

    <joint name="right_wheel_joint" type="revolute">
      <parent>base_link</parent>
      <child>right_wheel</child>
      <axis>
        <xyz>0 1 0</xyz>
      </axis>
    </joint>

    <joint name="caster_joint" type="fixed">
      <parent>base_link</parent>
      <child>caster</child>
    </joint>
  </model>
</sdf>
